%description:
Tests that errors in handleMessage() are properly caught and displayed in Cmdenv,
and finish() doesn't get called.

%module: Module

class Module : public cSimpleModule
{
  public:
    virtual void initialize();
    virtual void handleMessage(cMessage *msg);
    virtual void finish();
};

Define_Module(Module);

void Module::initialize()
{
    scheduleAt(1.0, new cMessage("msg"));
}

void Module::handleMessage(cMessage *msg)
{
    throw std::runtime_error("something bad happened");
}

void Module::finish()
{
    ev << "finish called\n";
}

%exitcode: 1

%contains-regex: stdout
Error in module .*: std::runtime_error: something bad happened

%not-contains: stdout
finish called

